Workbook

Sheet df_arabica_clean
A1: Column1 | B1: ID | C1: Country of Origin | D1: Farm Name | E1: Lot Number | F1: Mill | G1: Company | H1: Altitude | I1: Altitud_Limpia | J1: Columna1 | K1: Region | L1: Producer | M1: Number of Bags | N1: Bag Weight | O1: In-Country Partner | P1: Harvest Year | Q1: Grading Date | R1: Owner | S1: Variety | T1: Status | U1: Processing Method | V1: Aroma | W1: Flavor | X1: Aftertaste | Y1: Acidity | Z1: Body | AA1: Balance | AB1: Uniformity | AC1: Clean Cup | AD1: Sweetness | AE1: Overall | AF1: Total Cup Points | AG1: Moisture Percentage | AH1: Category One Defects | AI1: Quakers | AJ1: Color | AK1: Category Two Defects | AL1: Expiration | AM1: Certification Body | AN1: Certification Address | AO1: Certification Contact | AP1: Promedio_TotalCup | AQ1: Muestras
A2: 182 | B2: 182 | C2: Vietnam | D2: Gaia Farms | E2: 221221 | F2: Hulling Facility | G2: Brew Baby Coffee Company | H2: 5400 | I2: =IF(df_arabica_clean[[#This Row],[Altitude]] <= 2500, df_arabica_clean[[#This Row],[Altitude]], ROUND(df_arabica_clean[[#This Row],[Altitude]] / 3.281, 0)) -> 1646 | J2: =IF(df_arabica_clean[[#This Row],[Altitude]]>2500,"Convertido","Original") -> Convertido | K2: Lam Dong Province | L2: Viet Coffee Company Limited | M2: 1 | N2: 1 kg | O2: Firedancer Coffee Consultants | P2: 2022 / 2023 | Q2: April 10th, 2023 | R2: Rodney Murray | S2: Catimor | T2: Completed | U2: Pulped natural / honey | V2: 7.5 | W2: 7.5 | X2: 7.25 | Y2: 7.42 | Z2: 7.42 | AA2: 7.42 | AB2: 10 | AC2: 10 | AD2: 10 | AE2: 7.33 | AF2: 81.83 | AG2: 11.2 | AH2: 0 | AI2: 0 | AJ2: green | AK2: 4 | AL2: April 9th, 2024 | AM2: Firedancer Coffee Consultants | AN2: 165 Commerce Drive, Ste 103 | AO2: Firedancer Coffee Consultants - | AP2: =AVERAGEIF(df_arabica_clean[Country of Origin],df_arabica_clean[[#This Row],[Country of Origin]],df_arabica_clean[Total Cup Points]) -> 82.8925 | AQ2: =+COUNTIF(df_arabica_clean[Country of Origin],df_arabica_clean[[#This Row],[Country of Origin]]) -> 4
A3: 60 | B3: 60 | C3: Guatemala | D3: SAN RAFAEL URIAS VALDES | E3: 11/54876/03 | F3: ECO COFFEE | G3: VALBROS, S. A. | H3: 4895 | I3: =IF(df_arabica_clean[[#This Row],[Altitude]] <= 2500, df_arabica_clean[[#This Row],[Altitude]], ROUND(df_arabica_clean[[#This Row],[Altitude]] / 3.281, 0)) -> 1492 | J3: =IF(df_arabica_clean[[#This Row],[Altitude]]>2500,"Convertido","Original") -> Convertido | K3: ANTIGUA GUATEMALA | L3: VALBROS, S. A. | M3: 66 | N3: 30 kg | O3: Asociacion Nacional Del Café | P3: 2021 / 2022 | Q3: May 19th, 2022 | R3: Angelica Paola Citan Lopez | S3: Bourbon | T3: Completed | U3: Natural / Dry | V3: 7.83 | W3: 8 | X3: 7.67 | Y3: 7.83 | Z3: 7.75 | AA3: 7.75 | AB3: 10 | AC3: 10 | AD3: 10 | AE3: 7.83 | AF3: 84.67 | AG3: 10.9 | AH3: 0 | AI3: 3 | AJ3: yellow-green | AK3: 2 | AL3: May 19th, 2023 | AM3: Asociacion Nacional Del Café | AN3: 5a Calle 0-50, Zona 14 Guatemala City, Guatemala 1014 | AO3: Brayan Cifuentes - | AP3: =AVERAGEIF(df_arabica_clean[Country of Origin],df_arabica_clean[[#This Row],[Country of Origin]],df_arabica_clean[Total Cup Points]) -> 84.301429 | AQ3: =+COUNTIF(df_arabica_clean[Country of Origin],df_arabica_clean[[#This Row],[Country of Origin]]) -> 21
A4: 205 | B4: 205 | C4: El Salvador | D4: Rosario de Maria II, Area de La Pila | E4: 0423A01 | F4: Optimum Coffee, San Salvador, El Salvador | G4: Aprentium Enterprises LLC | H4: 1200 | I4: =IF(df_arabica_clean[[#This Row],[Altitude]] <= 2500, df_arabica_clean[[#This Row],[Altitude]], ROUND(df_arabica_clean[[#This Row],[Altitude]] / 3.281, 0)) -> 1200 | J4: =IF(df_arabica_clean[[#This Row],[Altitude]]>2500,"Convertido","Original") -> Original | K4: Volcan de San Vicente, La Paz, El Salvador | L4: Roselia Yglesias | M4: 1 | N4: 2 kg | O4: Salvadoran Coffee Council | P4: 2023 | Q4: March 8th, 2023 | R4: Roselia Yglesias | S4: Maragogype | T4: Completed | U4: Natural / Dry | V4: 6.5 | W4: 6.75 | X4: 6.75 | Y4: 7.17 | Z4: 7.08 | AA4: 7 | AB4: 10 | AC4: 10 | AD4: 10 | AE4: 6.83 | AF4: 78.08 | AG4: 11 | AH4: 0 | AI4: 12 | AJ4: bluish-green | AK4: 13 | AL4: March 7th, 2024 | AM4: Salvadoran Coffee Council | AN4: Final 1a. Av. Norte y 13 Calle Pte., dentro de las instalaciones del MAG | AO4: Tomas Bonilla - (503) 2505-6600 | AP4: =AVERAGEIF(df_arabica_clean[Country of Origin],df_arabica_clean[[#This Row],[Country of Origin]],df_arabica_clean[Total Cup Points]) -> 81.532857 | AQ4: =+COUNTIF(df_arabica_clean[Country of Origin],df_arabica_clean[[#This Row],[Country of Origin]]) -> 7
A5: 166 | B5: 166 | C5: El Salvador | D5: Agua Caliente | E5: 1-74 | F5: Agua Caliente | G5: Consejo Salvadoreño del Café | H5: 1200 | I5: =IF(df_arabica_clean[[#This Row],[Altitude]] <= 2500, df_arabica_clean[[#This Row],[Altitude]], ROUND(df_arabica_clean[[#This Row],[Altitude]] / 3.281, 0)) -> 1200 | J5: =IF(df_arabica_clean[[#This Row],[Altitude]]>2500,"Convertido","Original") -> Original | K5: Apaneca - Ilamatepec | L5: J.J. Borja Nathan, S.A. | M5: 275 | N5: 69 kg | O5: Salvadoran Coffee Council | P5: 2021 / 2022 | Q5: July 7th, 2022 | R5: Consejo Salvadoreño del Café | S5: Bourbon | T5: Completed | U5: Washed / Wet | V5: 7.33 | W5: 7.67 | X5: 7.25 | Y5: 7.67 | Z5: 7.83 | AA5: 7.42 | AB5: 10 | AC5: 10 | AD5: 10 | AE5: 7.17 | AF5: 82.33 | AG5: 11.8 | AH5: 0 | AI5: 0 | AJ5: bluish-green | AK5: 0 | AL5: July 7th, 2023 | AM5: Salvadoran Coffee Council | AN5: Final 1a. Av. Norte y 13 Calle Pte., dentro de las instalaciones del MAG | AO5: Tomas Bonilla - (503) 2505-6600 | AP5: =AVERAGEIF(df_arabica_clean[Country of Origin],df_arabica_clean[[#This Row],[Country of Origin]],df_arabica_clean[Total Cup Points]) -> 81.532857 | AQ5: =+COUNTIF(df_arabica_clean[Country of Origin],df_arabica_clean[[#This Row],[Country of Origin]]) -> 7
A6: 76 | B6: 76 | C6: Ethiopia | D6: Bisrat Melaku Washing Station | E6: 0065 | F6: Washing Station | G6: Tadesse Desta import export | H6: 2361 | I6: =IF(df_arabica_clean[[#This Row],[Altitude]] <= 2500, df_arabica_clean[[#This Row],[Altitude]], ROUND(df_arabica_clean[[#This Row],[Altitude]] / 3.281, 0)) -> 2361 | J6: =IF(df_arabica_clean[[#This Row],[Altitude]]>2500,"Convertido","Original") -> Original | K6: Addis Ababa | L6: Bisrat Melaku | M6: 320 | N6: 60 kg | O6: METAD Agricultural Development plc | P6: 2021 / 2022 | Q6: September 19th, 2022 | R6: Tadesse Desta | S6: Ethiopian Heirlooms | T6: Completed | U6: Natural / Dry | V6: 7.83 | W6: 7.75 | X6: 7.58 | Y6: 7.92 | Z6: 8 | AA6: 7.5 | AB6: 10 | AC6: 10 | AD6: 10 | AE6: 7.75 | AF6: 84.33 | AG6: 11 | AH6: 0 | AI6: 5 | AJ6: yellow green | AK6: 4 | AL6: September 19th, 2023 | AM6: METAD Agricultural Development plc | AN6: BAWA Center, 3rd Floor (Gerji), Addis Ababa, Ethiopia | AO6: Aman Adinew (Emebet Dinku) - +251-116-292534, +251-911-519196 | AP6: =AVERAGEIF(df_arabica_clean[Country of Origin],df_arabica_clean[[#This Row],[Country of Origin]],df_arabica_clean[Total Cup Points]) -> 84.960909 | AQ6: =+COUNTIF(df_arabica_clean[Country of Origin],df_arabica_clean[[#This Row],[Country of Origin]]) -> 11
A7: 34 | B7: 34 | C7: Ethiopia | D7: Uraga Bisrat washing station | E7: 0065 | F7: dry mill | G7: TADESSE DESTA IMPORT & EXPORT | H7: 2150 | I7: =IF(df_arabica_clean[[#This Row],[Altitude]] <= 2500, df_arabica_clean[[#This Row],[Altitude]], ROUND(df_arabica_clean[[#This Row],[Altitude]] / 3.281, 0)) -> 2150 | J7: =IF(df_arabica_clean[[#This Row],[Altitude]]>2500,"Convertido","Original") -> Original | K7: Southern Ethiopia Guji | L7: Bisrat Melaku | M7: 320 | N7: 60 kg | O7: METAD Agricultural Development plc | P7: 2021 / 2022 | Q7: September 30th, 2022 | R7: Tadessa Desta Amene | S7: Ethiopian Heirlooms | T7: Completed | U7: Natural / Dry | V7: 8 | W7: 8.08 | X7: 8 | Y7: 8 | Z7: 7.67 | AA7: 7.75 | AB7: 10 | AC7: 10 | AD7: 10 | AE7: 7.83 | AF7: 85.33 | AG7: 12.3 | AH7: 0 | AI7: 3 | AJ7: yellow green | AK7: 4 | AL7: September 30th, 2023 | AM7: METAD Agricultural Development plc | AN7: BAWA Center, 3rd Floor (Gerji), Addis Ababa, Ethiopia | AO7: Aman Adinew (Emebet Dinku) - +251-116-292534, +251-911-519196 | AP7: =AVERAGEIF(df_arabica_clean[Country of Origin],df_arabica_clean[[#This Row],[Country of Origin]],df_arabica_clean[Total Cup Points]) -> 84.960909 | AQ7: =+COUNTIF(df_arabica_clean[Country of Origin],df_arabica_clean[[#This Row],[Country of Origin]]) -> 11
A8: 165 | B8: 165 | C8: El Salvador | D8: Agua Caliente | E8: 1-26 | F8: Agua Caliente | G8: Consejo Salvadoreño del Café | H8: 1200 | I8: =IF(df_arabica_clean[[#This Row],[Altitude]] <= 2500, df_arabica_clean[[#This Row],[Altitude]], ROUND(df_arabica_clean[[#This Row],[Altitude]] / 3.281, 0)) -> 1200 | J8: =IF(df_arabica_clean[[#This Row],[Altitude]]>2500,"Convertido","Original") -> Original | K8: Apaneca - Ilamatepec | L8: J.J. Borja Nathan, S.A. | M8: 600 | N8: 30 kg | O8: Salvadoran Coffee Council | P8: 2022 / 2023 | Q8: February 21st, 2023 | R8: Consejo Salvadoreño del Café | S8: Bourbon | T8: Completed | U8: Washed / Wet | V8: 7.5 | W8: 7.5 | X8: 7.42 | Y8: 7.42 | Z8: 7.42 | AA8: 7.67 | AB8: 10 | AC8: 10 | AD8: 10 | AE8: 7.42 | AF8: 82.33 | AG8: 12 | AH8: 0 | AI8: 7 | AJ8: green | AK8: 10 | AL8: February 21st, 2024 | AM8: Salvadoran Coffee Council | AN8: Final 1a. Av. Norte y 13 Calle Pte., dentro de las instalaciones del MAG | AO8: Tomas Bonilla - (503) 2505-6600 | AP8: =AVERAGEIF(df_arabica_clean[Country of Origin],df_arabica_clean[[#This Row],[Country of Origin]],df_arabica_clean[Total Cup Points]) -> 81.532857 | AQ8: =+COUNTIF(df_arabica_clean[Country of Origin],df_arabica_clean[[#This Row],[Country of Origin]]) -> 7
A9: 156 | B9: 156 | C9: El Salvador | D9: Agua Caliente | E9: 1-26 | F9: Agua Caliente | G9: Consejo Salvadoreño del Café | H9: 1200 | I9: =IF(df_arabica_clean[[#This Row],[Altitude]] <= 2500, df_arabica_clean[[#This Row],[Altitude]], ROUND(df_arabica_clean[[#This Row],[Altitude]] / 3.281, 0)) -> 1200 | J9: =IF(df_arabica_clean[[#This Row],[Altitude]]>2500,"Convertido","Original") -> Original | K9: Apaneca - Ilamatepec | L9: J.J. Borja Nathan, S.A. | M9: 600 | N9: 30 kg | O9: Salvadoran Coffee Council | P9: 2022 / 2023 | Q9: March 3rd, 2023 | R9: Consejo Salvadoreño del Café | S9: Bourbon | T9: Completed | U9: Washed / Wet | V9: 7.67 | W9: 7.33 | X9: 7.17 | Y9: 7.67 | Z9: 7.83 | AA9: 7.5 | AB9: 10 | AC9: 10 | AD9: 10 | AE9: 7.33 | AF9: 82.5 | AG9: 11.3 | AH9: 0 | AI9: 0 | AJ9: green | AK9: 2 | AL9: March 2nd, 2024 | AM9: Salvadoran Coffee Council | AN9: Final 1a. Av. Norte y 13 Calle Pte., dentro de las instalaciones del MAG | AO9: Tomas Bonilla - (503) 2505-6600 | AP9: =AVERAGEIF(df_arabica_clean[Country of Origin],df_arabica_clean[[#This Row],[Country of Origin]],df_arabica_clean[Total Cup Points]) -> 81.532857 | AQ9: =+COUNTIF(df_arabica_clean[Country of Origin],df_arabica_clean[[#This Row],[Country of Origin]]) -> 7
A10: 100 | B10: 100 | C10: Ethiopia | D10: Gerbicho Lela Cooperative | E10: 1 | F10: Sidama Coffee Farmers Cooperative Union | G10: Taylor Winch Coffee Ltd | H10: 2000 | I10: =IF(df_arabica_clean[[#This Row],[Altitude]] <= 2500, df_arabica_clean[[#This Row],[Altitude]], ROUND(df_arabica_clean[[#This Row],[Altitude]] / 3.281, 0)) -> 2000 | J10: =IF(df_arabica_clean[[#This Row],[Altitude]]>2500,"Convertido","Original") -> Original | K10: Sidama | L10: Sidama Coffee Farmers Cooperative Union | M10: 100 | N10: 60 kg | O10: Kenya Coffee Traders Association | P10: 2021 / 2022 | Q10: September 9th, 2022 | R10: Taylor Winch (Coffee) Ltd. | S10: Ethiopian Heirlooms | T10: Completed | U10: Washed / Wet | V10: 7.83 | W10: 7.67 | X10: 7.5 | Y10: 7.92 | Z10: 7.5 | AA10: 7.67 | AB10: 10 | AC10: 10 | AD10: 10 | AE10: 7.75 | AF10: 83.83 | AG10: 12 | AH10: 0 | AI10: 0 | AJ10: green | AK10: 12 | AL10: September 9th, 2023 | AM10: Kenya Coffee Traders Association | AN10: P.O. Box 646 00100Nairobi, Kenya, Denniss Pritt Road, Opposite St Georges Girls Secondary School | AO10: Benson Kibicho Kamau - +254 786 821 621 | AP10: =AVERAGEIF(df_arabica_clean[Country of Origin],df_arabica_clean[[#This Row],[Country of Origin]],df_arabica_clean[Total Cup Points]) -> 84.960909 | AQ10: =+COUNTIF(df_arabica_clean[Country of Origin],df_arabica_clean[[#This Row],[Country of Origin]]) -> 11
A11: 33 | B11: 33 | C11: Ethiopia | D11: Eshetu farm | E11: Washed Limmu | F11: Lata Agri export | G11: Alo Coffee | H11: 1950 | I11: =IF(df_arabica_clean[[#This Row],[Altitude]] <= 2500, df_arabica_clean[[#This Row],[Altitude]], ROUND(df_arabica_clean[[#This Row],[Altitude]] / 3.281, 0)) -> 1950 | J11: =IF(df_arabica_clean[[#This Row],[Altitude]]>2500,"Convertido","Original") -> Original | K11: Oromia | L11: Eshetu | M11: 320 | N11: 60 kg | O11: METAD Agricultural Development plc | P11: 2021 / 2022 | Q11: June 6th, 2022 | R11: Tamiru Tadesse Tesema | S11: Ethiopian Heirlooms | T11: Completed | U11: Washed / Wet | V11: 7.67 | W11: 7.83 | X11: 7.83 | Y11: 8 | Z11: 8 | AA11: 8 | AB11: 10 | AC11: 10 | AD11: 10 | AE11: 8 | AF11: 85.33 | AG11: 9.9 | AH11: 0 | AI11: 2 | AJ11: green | AK11: 3 | AL11: June 6th, 2023 | AM11: METAD Agricultural Development plc | AN11: BAWA Center, 3rd Floor (Gerji), Addis Ababa, Ethiopia | AO11: Aman Adinew (Emebet Dinku) - +251-116-292534, +251-911-519196 | AP11: =AVERAGEIF(df_arabica_clean[Country of Origin],df_arabica_clean[[#This Row],[Country of Origin]],df_arabica_clean[Total Cup Points]) -> 84.960909 | AQ11: =+COUNTIF(df_arabica_clean[Country of Origin],df_arabica_clean[[#This Row],[Country of Origin]]) -> 11
A12: 71 | B12: 71 | C12: Ethiopia | D12: TRACON TRADING PLC | E12: 0712 | F12: 5.2Ha | G12: Tracon Trading PLC | H12: 1943 | I12: =IF(df_arabica_clean[[#This Row],[Altitude]] <= 2500, df_arabica_clean[[#This Row],[Altitude]], ROUND(df_arabica_clean[[#This Row],[Altitude]] / 3.281, 0)) -> 1943 | J12: =IF(df_arabica_clean[[#This Row],[Altitude]]>2500,"Convertido","Original") -> Original | K12: Ethiopia | L12: TRACON TRADING PLC | M12: 584 | N12: 30 kg | O12: Blossom Valley International宸嶧國際 | P12: 2021 / 2022 | Q12: August 23rd, 2022 | R12: 李晓斐 LI XIAO FEI | S12: Ethiopian Heirlooms | T12: Completed | U12: Washed / Wet | V12: 7.92 | W12: 7.83 | X12: 7.75 | Y12: 7.92 | Z12: 7.58 | AA12: 7.67 | AB12: 10 | AC12: 10 | AD12: 10 | AE12: 7.83 | AF12: 84.5 | AG12: 10.9 | AH12: 0 | AI12: 0 | AJ12: green | AK12: 9 | AL12: August 23rd, 2023 | AM12: Blossom Valley International宸嶧國際 | AN12: No.72 Mo-Fan St. Taiwan Zip: 403 | AO12: Damon Chen陳嘉峻 - +886423022323 | AP12: =AVERAGEIF(df_arabica_clean[Country of Origin],df_arabica_clean[[#This Row],[Country of Origin]],df_arabica_clean[Total Cup Points]) -> 84.960909 | AQ12: =+COUNTIF(df_arabica_clean[Country of Origin],df_arabica_clean[[#This Row],[Country of Origin]]) -> 11
A13: 43 | B13: 43 | C13: Uganda | D13: Gideon Kule | E13: 7938 | F13: Dry Mill | G13: Kyagalanyi Coffee Limited | H13: 1905 | I13: =IF(df_arabica_clean[[#This Row],[Altitude]] <= 2500, df_arabica_clean[[#This Row],[Altitude]], ROUND(df_arabica_clean[[#This Row],[Altitude]] / 3.281, 0)) -> 1905 | J13: =IF(df_arabica_clean[[#This Row],[Altitude]]>2500,"Convertido","Original") -> Original | K13: Rwenzori | L13: Kyagalanyi coffee limited | M13: 320 | N13: 60 kg | O13: Uganda Coffee Development Authority | P13: 2021 / 2022 | Q13: June 29th, 2022 | R13: KYAGALANYI COFFEE LIMITED | S13: SL14 | T13: Completed | U13: Washed / Wet | V13: 8 | W13: 7.92 | X13: 7.75 | Y13: 7.75 | Z13: 7.75 | AA13: 7.92 | AB13: 10 | AC13: 10 | AD13: 10 | AE13: 7.92 | AF13: 85 | AG13: 11 | AH13: 0 | AI13: 0 | AJ13: green | AK13: 1 | AL13: June 29th, 2023 | AM13: Uganda Coffee Development Authority | AN13: Coffee House, Plot 35, Jinja Road, P.O. Box 7267, Kampala, Uganda | AO13: Brenda Kamara Kemigisha Mangeni - 256773040119 | AP13: =AVERAGEIF(df_arabica_clean[Country of Origin],df_arabica_clean[[#This Row],[Country of Origin]],df_arabica_clean[Total Cup Points]) -> 83.916667 | AQ13: =+COUNTIF(df_arabica_clean[Country of Origin],df_arabica_clean[[#This Row],[Country of Origin]]) -> 3
... A29: 201 | B29: 201 | C29: Brazil | D29: Various farm | E29: 002/1738/0029 | F29: Dry mill | G29: marubeni | H29: 1200 | I29: =IF(df_arabica_clean[[#This Row],[Altitude]] <= 2500, df_arabica_clean[[#This Row],[Altitude]], ROUND(df_arabica_clean[[#This Row],[Altitude]] / 3.281, 0)) -> 1200 | J29: =IF(df_arabica_clean[[#This Row],[Altitude]]>2500,"Convertido","Original") -> Original | K29: Alta Mogiana-Ibiraci | L29: COCAPIL | M29: 440 | N29: 60 kg | O29: Japan Coffee Exchange | P29: 2021 / 2022 | Q29: July 20th, 2022 | R29: Ikuto Uehara | S29: Catuai and Mundo Novo | T29: Completed | U29: Natural / Dry | V29: 7.25 | W29: 7.17 | X29: 7.17 | Y29: 7.08 | Z29: 7.17 | AA29: 7.17 | AB29: 10 | AC29: 10 | AD29: 10 | AE29: 7.17 | AF29: 80.17 | AG29: 11.6 | AH29: 0 | AI29: 1 | AJ29: greenish | AK29: 2 | AL29: July 20th, 2023 | AM29: Japan Coffee Exchange | AN29: 〒413-0002 静岡県熱海市伊豆山１１７３−５８ 1173-58 Izusan, Atami, Shizuoka, 413-0002 JAPAN | AO29: 松澤 宏樹 Koju Matsuzawa - +81(0)9085642901 | AP29: =AVERAGEIF(df_arabica_clean[Country of Origin],df_arabica_clean[[#This Row],[Country of Origin]],df_arabica_clean[Total Cup Points]) -> 81.883 | AQ29: =+COUNTIF(df_arabica_clean[Country of Origin],df_arabica_clean[[#This Row],[Country of Origin]]) -> 10
A30: 194 | B30: 194 | C30: Brazil | D30: Various farm | E30: 0038 | F30: Dry Mill of Cocapil | G30: Marubeni Corporation | H30: 1200 | I30: =IF(df_arabica_clean[[#This Row],[Altitude]] <= 2500, df_arabica_clean[[#This Row],[Altitude]], ROUND(df_arabica_clean[[#This Row],[Altitude]] / 3.281, 0)) -> 1200 | J30: =IF(df_arabica_clean[[#This Row],[Altitude]]>2500,"Convertido","Original") -> Original | K30: Alta Mogiana-Ibiraci | L30: Cocapil | M30: 440 | N30: 60 kg | O30: Japan Coffee Exchange | P30: 2022 / 2023 | Q30: April 17th, 2023 | R30: Ikuto Uehara | T30: Completed | U30: Natural / Dry | V30: 7.42 | W30: 7.42 | X30: 7.25 | Y30: 7.25 | Z30: 7.17 | AA30: 7.25 | AB30: 10 | AC30: 10 | AD30: 10 | AE30: 7.25 | AF30: 81 | AG30: 10.6 | AH30: 0 | AI30: 2 | AJ30: greenish | AK30: 1 | AL30: April 16th, 2024 | AM30: Japan Coffee Exchange | AN30: 〒413-0002 静岡県熱海市伊豆山１１７３−５８ 1173-58 Izusan, Atami, Shizuoka, 413-0002 JAPAN | AO30: 松澤 宏樹 Koju Matsuzawa - +81(0)9085642901 | AP30: =AVERAGEIF(df_arabica_clean[Country of Origin],df_arabica_clean[[#This Row],[Country of Origin]],df_arabica_clean[Total Cup Points]) -> 81.883 | AQ30: =+COUNTIF(df_arabica_clean[Country of Origin],df_arabica_clean[[#This Row],[Country of Origin]]) -> 10
A31: 25 | B31: 25 | C31: Brazil | D31: Fazenda Recreio | E31: Arara 1 | F31: Dry mill | G31: WIT wealth, investments & trust | H31: 1250 | I31: =IF(df_arabica_clean[[#This Row],[Altitude]] <= 2500, df_arabica_clean[[#This Row],[Altitude]], ROUND(df_arabica_clean[[#This Row],[Altitude]] / 3.281, 0)) -> 1250 | J31: =IF(df_arabica_clean[[#This Row],[Altitude]]>2500,"Convertido","Original") -> Original | K31: Região Vulcânica | L31: Diogo T. Dias de Macedo | M31: 25 | N31: 60 kg | O31: Brazil Specialty Coffee Association | P31: 2022 | Q31: January 6th, 2023 | R31: Andre Clark | T31: Completed | U31: Pulped natural / honey | V31: 7.83 | W31: 8.08 | X31: 7.83 | Y31: 7.92 | Z31: 8 | AA31: 7.83 | AB31: 10 | AC31: 10 | AD31: 10 | AE31: 8 | AF31: 85.5 | AG31: 11.3 | AH31: 2 | AI31: 0 | AJ31: green | AK31: 3 | AL31: January 6th, 2024 | AM31: Brazil Specialty Coffee Association | AN31: Rua Gaspar Batista Paiva, 416 – Santa Luiza Varginha/MG – Brazil | AO31: Chris Allen - 55 35 3212-4705 | AP31: =AVERAGEIF(df_arabica_clean[Country of Origin],df_arabica_clean[[#This Row],[Country of Origin]],df_arabica_clean[Total Cup Points]) -> 81.883 | AQ31: =+COUNTIF(df_arabica_clean[Country of Origin],df_arabica_clean[[#This Row],[Country of Origin]]) -> 10
A32: 197 | B32: 197 | C32: Nicaragua | D32: Sajonia Estate Coffee S.A. | E32: 1 | F32: Sajonia Estate Coffee S.A. | G32: SAJONIA ESTATE COFFEE S.A. | H32: 1000 | I32: =IF(df_arabica_clean[[#This Row],[Altitude]] <= 2500, df_arabica_clean[[#This Row],[Altitude]], ROUND(df_arabica_clean[[#This Row],[Altitude]] / 3.281, 0)) -> 1000 | J32: =IF(df_arabica_clean[[#This Row],[Altitude]]>2500,"Convertido","Original") -> Original | K32: Jinotega | L32: Sajonia Estate Coffee S.A. | M32: 275 | N32: 69 kg | O32: Asociación de Cafés Especiales de Nicaragua | P32: 2022 / 2023 | Q32: April 20th, 2023 | R32: SAJONIA ESTATE COFFEE S.A. | S32: Sarchimor | T32: Completed | U32: Washed / Wet | V32: 7.42 | W32: 7.17 | X32: 7 | Y32: 7.08 | Z32: 7.42 | AA32: 7.17 | AB32: 10 | AC32: 10 | AD32: 10 | AE32: 7.17 | AF32: 80.42 | AG32: 11.2 | AH32: 0 | AI32: 0 | AJ32: green | AK32: 5 | AL32: April 19th, 2024 | AM32: Asociación de Cafés Especiales de Nicaragua | AN32: Del Hotel Seminole 2 C al lago, 1 C arriba. | AO32: Maria Ines Benavidez Toval - 011-(505)-8396 4717 | AP32: =AVERAGEIF(df_arabica_clean[Country of Origin],df_arabica_clean[[#This Row],[Country of Origin]],df_arabica_clean[Total Cup Points]) -> 81.892857 | AQ32: =+COUNTIF(df_arabica_clean[Country of Origin],df_arabica_clean[[#This Row],[Country of Origin]]) -> 7
A33: 35 | B33: 35 | C33: Ethiopia | D33: YHAENU PLC FARM | E33: 1 | F33: GUJI COFFEE EXPORT P.L.C | G33: yhaenu plc | H33: 1700 | I33: =IF(df_arabica_clean[[#This Row],[Altitude]] <= 2500, df_arabica_clean[[#This Row],[Altitude]], ROUND(df_arabica_clean[[#This Row],[Altitude]] / 3.281, 0)) -> 1700 | J33: =IF(df_arabica_clean[[#This Row],[Altitude]]>2500,"Convertido","Original") -> Original | K33: OROMIA | L33: YHAENU PLC | M33: 320 | N33: 19200 kg | O33: METAD Agricultural Development plc | P33: 2021 / 2022 | Q33: December 12th, 2022 | R33: YHAENU PLC | S33: Ethiopian Heirlooms | T33: Completed | U33: Washed / Wet | V33: 7.92 | W33: 7.75 | X33: 7.83 | Y33: 8.17 | Z33: 8 | AA33: 7.75 | AB33: 10 | AC33: 10 | AD33: 10 | AE33: 7.83 | AF33: 85.25 | AG33: 9.4 | AH33: 0 | AI33: 1 | AJ33: greenish | AK33: 1 | AL33: December 12th, 2023 | AM33: METAD Agricultural Development plc | AN33: BAWA Center, 3rd Floor (Gerji), Addis Ababa, Ethiopia | AO33: Aman Adinew (Emebet Dinku) - +251-116-292534, +251-911-519196 | AP33: =AVERAGEIF(df_arabica_clean[Country of Origin],df_arabica_clean[[#This Row],[Country of Origin]],df_arabica_clean[Total Cup Points]) -> 84.960909 | AQ33: =+COUNTIF(df_arabica_clean[Country of Origin],df_arabica_clean[[#This Row],[Country of Origin]]) -> 11
A34: 116 | B34: 116 | C34: Ethiopia | D34: YHAENU PLC FARM | E34: 1 | F34: GUJI COFFEE EXPORT P.L.C | G34: yhaenu plc | H34: 1700 | I34: =IF(df_arabica_clean[[#This Row],[Altitude]] <= 2500, df_arabica_clean[[#This Row],[Altitude]], ROUND(df_arabica_clean[[#This Row],[Altitude]] / 3.281, 0)) -> 1700 | J34: =IF(df_arabica_clean[[#This Row],[Altitude]]>2500,"Convertido","Original") -> Original | K34: OROMIA | L34: YHAENU PLC | M34: 320 | N34: 19200 kg | O34: METAD Agricultural Development plc | P34: 2021 / 2022 | Q34: November 30th, 2022 | R34: YHAENU PLC | S34: Ethiopian Heirlooms | T34: Completed | U34: Washed / Wet | V34: 7.42 | W34: 7.42 | X34: 7.42 | Y34: 8 | Z34: 7.92 | AA34: 7.67 | AB34: 10 | AC34: 10 | AD34: 10 | AE34: 7.67 | AF34: 83.5 | AG34: 10.4 | AH34: 0 | AI34: 1 | AJ34: greenish | AK34: 11 | AL34: November 30th, 2023 | AM34: METAD Agricultural Development plc | AN34: BAWA Center, 3rd Floor (Gerji), Addis Ababa, Ethiopia | AO34: Aman Adinew (Emebet Dinku) - +251-116-292534, +251-911-519196 | AP34: =AVERAGEIF(df_arabica_clean[Country of Origin],df_arabica_clean[[#This Row],[Country of Origin]],df_arabica_clean[Total Cup Points]) -> 84.960909 | AQ34: =+COUNTIF(df_arabica_clean[Country of Origin],df_arabica_clean[[#This Row],[Country of Origin]]) -> 11
A35: 196 | B35: 196 | C35: Nicaragua | D35: EXPORTADORA ATLANTIC S.A | E35: 017/053/0603 | F35: Lavado | G35: ISHIMITSU | H35: 1100 | I35: =IF(df_arabica_clean[[#This Row],[Altitude]] <= 2500, df_arabica_clean[[#This Row],[Altitude]], ROUND(df_arabica_clean[[#This Row],[Altitude]] / 3.281, 0)) -> 1100 | J35: =IF(df_arabica_clean[[#This Row],[Altitude]]>2500,"Convertido","Original") -> Original | L35: Varios Productores | M35: 275 | N35: 69 kg | O35: Japan Coffee Exchange | P35: 2021 | Q35: July 11th, 2022 | R35: 丸山花織 | S35: Caturra | T35: Completed | U35: Washed / Wet | V35: 7.25 | W35: 7.25 | X35: 7.17 | Y35: 7.33 | Z35: 7.08 | AA35: 7.25 | AB35: 10 | AC35: 10 | AD35: 10 | AE35: 7.17 | AF35: 80.5 | AG35: 11.5 | AH35: 0 | AI35: 1 | AJ35: greenish | AK35: 3 | AL35: July 11th, 2023 | AM35: Japan Coffee Exchange | AN35: 〒413-0002 静岡県熱海市伊豆山１１７３−５８ 1173-58 Izusan, Atami, Shizuoka, 413-0002 JAPAN | AO35: 松澤 宏樹 Koju Matsuzawa - +81(0)9085642901 | AP35: =AVERAGEIF(df_arabica_clean[Country of Origin],df_arabica_clean[[#This Row],[Country of Origin]],df_arabica_clean[Total Cup Points]) -> 81.892857 | AQ35: =+COUNTIF(df_arabica_clean[Country of Origin],df_arabica_clean[[#This Row],[Country of Origin]]) -> 7
A36: 163 | B36: 163 | C36: Nicaragua | D36: Finca Aurora | E36: 1 | F36: Beneficio Seco Finca Aurora | G36: Mr.Brown Cafe | H36: 1200 | I36: =IF(df_arabica_clean[[#This Row],[Altitude]] <= 2500, df_arabica_clean[[#This Row],[Altitude]], ROUND(df_arabica_clean[[#This Row],[Altitude]] / 3.281, 0)) -> 1200 | J36: =IF(df_arabica_clean[[#This Row],[Altitude]]>2500,"Convertido","Original") -> Original | K36: Matagalpa, Nicaragua | L36: Sabio Coffee - Enrique Ferrufino & Tania Ferrufino | M36: 275 | N36: 69 kg | O36: Taiwan Coffee Laboratory 台灣咖啡研究室 | P36: 2021 / 2022 | Q36: December 30th, 2022 | R36: MR.BROWN CAFE | S36: Caturra-Catuai | T36: Completed | U36: Washed / Wet | V36: 7.58 | W36: 7.58 | X36: 7.42 | Y36: 7.42 | Z36: 7.5 | AA36: 7.5 | AB36: 10 | AC36: 10 | AD36: 10 | AE36: 7.42 | AF36: 82.42 | AG36: 11.4 | AH36: 0 | AI36: 0 | AJ36: bluish-green | AK36: 0 | AL36: December 30th, 2023 | AM36: Taiwan Coffee Laboratory 台灣咖啡研究室 | AN36: QAHWAH CO., LTD 4F, No. 225, Sec. 3, Beixin Rd., Xindian Dist. New Taipei City, Taiwan | AO36: Lin, Jen-An Neil 林仁安 - 886-289116612 | AP36: =AVERAGEIF(df_arabica_clean[Country of Origin],df_arabica_clean[[#This Row],[Country of Origin]],df_arabica_clean[Total Cup Points]) -> 81.892857 | AQ36: =+COUNTIF(df_arabica_clean[Country of Origin],df_arabica_clean[[#This Row],[Country of Origin]]) -> 7
A37: 203 | B37: 203 | C37: Nicaragua | D37: Finca San Felipe | E37: 017-053-0155 | F37: Beneficio Atlantic Sébaco | G37: Exportadora Atlantic S.A | H37: 1200 | I37: =IF(df_arabica_clean[[#This Row],[Altitude]] <= 2500, df_arabica_clean[[#This Row],[Altitude]], ROUND(df_arabica_clean[[#This Row],[Altitude]] / 3.281, 0)) -> 1200 | J37: =IF(df_arabica_clean[[#This Row],[Altitude]]>2500,"Convertido","Original") -> Original | K37: Matagalpa | L37: Exportadora Atlantic S.A. | M37: 300 | N37: 30 kg | O37: Asociación de Cafés Especiales de Nicaragua | P37: 2022 / 2023 | Q37: March 3rd, 2023 | R37: Exportadora Atlantic, S.A. | S37: SHG | T37: Completed | U37: Natural / Dry | V37: 7.33 | W37: 7.08 | X37: 6.75 | Y37: 7.17 | Z37: 7.42 | AA37: 7.17 | AB37: 10 | AC37: 10 | AD37: 10 | AE37: 7.08 | AF37: 80 | AG37: 10.4 | AH37: 0 | AI37: 2 | AJ37: green | AK37: 12 | AL37: March 2nd, 2024 | AM37: Asociación de Cafés Especiales de Nicaragua | AN37: Del Hotel Seminole 2 C al lago, 1 C arriba. | AO37: Maria Ines Benavidez Toval - 011-(505)-8396 4717 | AP37: =AVERAGEIF(df_arabica_clean[Country of Origin],df_arabica_clean[[#This Row],[Country of Origin]],df_arabica_clean[Total Cup Points]) -> 81.892857 | AQ37: =+COUNTIF(df_arabica_clean[Country of Origin],df_arabica_clean[[#This Row],[Country of Origin]]) -> 7
A38: 53 | B38: 53 | C38: Tanzania, United Republic Of | D38: IYENGA | E38: S59588/P03989 | F38: CITY COFFEE LTD | G38: VOLCAFE/TaylorWinch Tanzania Ltd | H38: 1654 | I38: =IF(df_arabica_clean[[#This Row],[Altitude]] <= 2500, df_arabica_clean[[#This Row],[Altitude]], ROUND(df_arabica_clean[[#This Row],[Altitude]] / 3.281, 0)) -> 1654 | J38: =IF(df_arabica_clean[[#This Row],[Altitude]]>2500,"Convertido","Original") -> Original | K38: Mbeya | L38: IYENGA AMCOS | M38: 620 | N38: 30 kg | O38: Kenya Coffee Traders Association | P38: 2022 / 2023 | Q38: November 9th, 2022 | R38: Balam Hinyula | S38: Bourbon | T38: Completed | U38: Washed / Wet | V38: 7.92 | W38: 7.75 | X38: 7.75 | Y38: 7.92 | Z38: 7.83 | AA38: 7.83 | AB38: 10 | AC38: 10 | AD38: 10 | AE38: 7.83 | AF38: 84.83 | AG38: 11.2 | AH38: 0 | AI38: 0 | AJ38: greenish | AK38: 0 | AL38: November 9th, 2023 | AM38: Kenya Coffee Traders Association | AN38: P.O. Box 646 00100Nairobi, Kenya, Denniss Pritt Road, Opposite St Georges Girls Secondary School | AO38: Benson Kibicho Kamau - +254 786 821 621 | AP38: =AVERAGEIF(df_arabica_clean[Country of Origin],df_arabica_clean[[#This Row],[Country of Origin]],df_arabica_clean[Total Cup Points]) -> 84.735 | AQ38: =+COUNTIF(df_arabica_clean[Country of Origin],df_arabica_clean[[#This Row],[Country of Origin]]) -> 6
A39: 147 | B39: 147 | C39: Nicaragua | D39: Finca San Felipe | E39: 017-053-0017 | F39: Beneficio Atlantic Sébaco | G39: Exportadora Atlantic S.A | H39: 1200 | I39: =IF(df_arabica_clean[[#This Row],[Altitude]] <= 2500, df_arabica_clean[[#This Row],[Altitude]], ROUND(df_arabica_clean[[#This Row],[Altitude]] / 3.281, 0)) -> 1200 | J39: =IF(df_arabica_clean[[#This Row],[Altitude]]>2500,"Convertido","Original") -> Original | K39: Matagalpa | L39: Exportadora Atlantic S.A. | M39: 275 | N39: 69 kg | O39: Asociación de Cafés Especiales de Nicaragua | P39: 2022 / 2023 | Q39: January 30th, 2023 | R39: Exportadora Atlantic, S.A. | S39: SHG | T39: Completed | U39: Natural / Dry | V39: 7.33 | W39: 7.58 | X39: 7.25 | Y39: 7.33 | Z39: 7.75 | AA39: 8.17 | AB39: 10 | AC39: 10 | AD39: 10 | AE39: 7.33 | AF39: 82.75 | AG39: 10.5 | AH39: 5 | AI39: 2 | AJ39: green | AK39: 1 | AL39: January 30th, 2024 | AM39: Asociación de Cafés Especiales de Nicaragua | AN39: Del Hotel Seminole 2 C al lago, 1 C arriba. | AO39: Maria Ines Benavidez Toval - 011-(505)-8396 4717 | AP39: =AVERAGEIF(df_arabica_clean[Country of Origin],df_arabica_clean[[#This Row],[Country of Origin]],df_arabica_clean[Total Cup Points]) -> 81.892857 | AQ39: =+COUNTIF(df_arabica_clean[Country of Origin],df_arabica_clean[[#This Row],[Country of Origin]]) -> 7
A40: 155 | B40: 155 | C40: Nicaragua | D40: Finca Las Dos Marias | E40: 4 -3.1 | F40: Compare Coperativo Condega, Esteli, Nicaragua | G40: NicaNoLA Coffee | H40: 1350 | I40: =IF(df_arabica_clean[[#This Row],[Altitude]] <= 2500, df_arabica_clean[[#This Row],[Altitude]], ROUND(df_arabica_clean[[#This Row],[Altitude]] / 3.281, 0)) -> 1350 | J40: =IF(df_arabica_clean[[#This Row],[Altitude]]>2500,"Convertido","Original") -> Original | K40: ESTELI | L40: NicaNoLA Coffee | M40: 120 | N40: 45 kg | O40: Specialty Coffee Association | P40: 2021 / 2022 | Q40: June 20th, 2022 | R40: rene j alcebo | S40: Parainema | T40: Completed | U40: Washed / Wet | V40: 7.5 | W40: 7.58 | X40: 7.42 | Y40: 7.58 | Z40: 7.5 | AA40: 7.58 | AB40: 10 | AC40: 10 | AD40: 10 | AE40: 7.42 | AF40: 82.58 | AG40: 10.1 | AH40: 0 | AI40: 0 | AJ40: green | AK40: 0 | AL40: June 20th, 2023 | AM40: Specialty Coffee Association | AN40: *CURRENTLY NOT ACCEPTING SAMPLES** | AO40: Brit Amell (CQI) - bamell@coffeeinstitute.org - | AP40: =AVERAGEIF(df_arabica_clean[Country of Origin],df_arabica_clean[[#This Row],[Country of Origin]],df_arabica_clean[Total Cup Points]) -> 81.892857 | AQ40: =+COUNTIF(df_arabica_clean[Country of Origin],df_arabica_clean[[#This Row],[Country of Origin]]) -> 7
A41: 89 | B41: 89 | C41: Tanzania, United Republic Of | D41: KONGONI ESTATE | E41: CN 4127230031/P-9139 | F41: RAFIKI MILL | G41: C.DORMAN SEZ LTD | H41: 1600 | I41: =IF(df_arabica_clean[[#This Row],[Altitude]] <= 2500, df_arabica_clean[[#This Row],[Altitude]], ROUND(df_arabica_clean[[#This Row],[Altitude]] / 3.281, 0)) -> 1600 | J41: =IF(df_arabica_clean[[#This Row],[Altitude]]>2500,"Convertido","Original") -> Original | K41: ARUSHA | L41: DORMAN (T) LTD | M41: 200 | N41: 60 kg | O41: Kenya Coffee Traders Association | P41: 2022 / 2023 | Q41: January 3rd, 2023 | R41: Gilbert Maina | S41: Bourbon | T41: Completed | U41: Washed / Wet | V41: 7.58 | W41: 7.67 | X41: 7.75 | Y41: 7.75 | Z41: 7.75 | AA41: 7.75 | AB41: 10 | AC41: 10 | AD41: 10 | AE41: 7.75 | AF41: 84 | AG41: 9.8 | AH41: 0 | AI41: 0 | AJ41: greenish | AK41: 3 | AL41: January 3rd, 2024 | AM41: Kenya Coffee Traders Association | AN41: P.O. Box 646 00100Nairobi, Kenya, Denniss Pritt Road, Opposite St Georges Girls Secondary School | AO41: Benson Kibicho Kamau - +254 786 821 621 | AP41: =AVERAGEIF(df_arabica_clean[Country of Origin],df_arabica_clean[[#This Row],[Country of Origin]],df_arabica_clean[Total Cup Points]) -> 84.735 | AQ41: =+COUNTIF(df_arabica_clean[Country of Origin],df_arabica_clean[[#This Row],[Country of Origin]]) -> 6
A42: 64 | B42: 64 | C42: Nicaragua | D42: Finca Las Dos Marias | E42: 10 1.1 | F42: Compare Coperativo Condega, Esteli, Nicaragua | G42: NicaNoLA Coffee | H42: 1350 | I42: =IF(df_arabica_clean[[#This Row],[Altitude]] <= 2500, df_arabica_clean[[#This Row],[Altitude]], ROUND(df_arabica_clean[[#This Row],[Altitude]] / 3.281, 0)) -> 1350 | J42: =IF(df_arabica_clean[[#This Row],[Altitude]]>2500,"Convertido","Original") -> Original | K42: ESTELI | L42: NicaNoLA Coffee | M42: 74 | N42: 45 kg | O42: Specialty Coffee Association | P42: 2021 / 2022 | Q42: June 9th, 2022 | R42: rene j alcebo | S42: Catrenic | T42: Completed | U42: Natural / Dry | V42: 7.92 | W42: 7.75 | X42: 7.67 | Y42: 7.67 | Z42: 7.83 | AA42: 7.75 | AB42: 10 | AC42: 10 | AD42: 10 | AE42: 8 | AF42: 84.58 | AG42: 9.9 | AH42: 1 | AI42: 0 | AJ42: green | AK42: 2 | AL42: June 9th, 2023 | AM42: Specialty Coffee Association | AN42: *CURRENTLY NOT ACCEPTING SAMPLES** | AO42: Brit Amell (CQI) - bamell@coffeeinstitute.org - | AP42: =AVERAGEIF(df_arabica_clean[Country of Origin],df_arabica_clean[[#This Row],[Country of Origin]],df_arabica_clean[Total Cup Points]) -> 81.892857 | AQ42: =+COUNTIF(df_arabica_clean[Country of Origin],df_arabica_clean[[#This Row],[Country of Origin]]) -> 7
A43: 199 | B43: 199 | C43: Peru | D43: Fundo La Libertad | E43: PR137 | F43: Callao Plant | G43: Itochu Corporation | H43: 1600 | I43: =IF(df_arabica_clean[[#This Row],[Altitude]] <= 2500, df_arabica_clean[[#This Row],[Altitude]], ROUND(df_arabica_clean[[#This Row],[Altitude]] / 3.281, 0)) -> 1600 | J43: =IF(df_arabica_clean[[#This Row],[Altitude]]>2500,"Convertido","Original") -> Original | K43: Chanchamayo, Lamerced | L43: Sandro Crispin Espiritu | M43: 275 | N43: 69 kg | O43: Japan Coffee Exchange | P43: 2022 / 2023 | Q43: June 10th, 2022 | R43: Kiichiro Iwata | S43: Caturra | T43: Completed | U43: Washed / Wet | V43: 7.5 | W43: 7.25 | X43: 7.17 | Y43: 7.17 | Z43: 7.17 | AA43: 7.08 | AB43: 10 | AC43: 10 | AD43: 10 | AE43: 7 | AF43: 80.33 | AG43: 11.8 | AH43: 0 | AI43: 6 | AJ43: greenish | AK43: 11 | AL43: June 10th, 2023 | AM43: Japan Coffee Exchange | AN43: 〒413-0002 静岡県熱海市伊豆山１１７３−５８ 1173-58 Izusan, Atami, Shizuoka, 413-0002 JAPAN | AO43: 松澤 宏樹 Koju Matsuzawa - +81(0)9085642901 | AP43: =AVERAGEIF(df_arabica_clean[Country of Origin],df_arabica_clean[[#This Row],[Country of Origin]],df_arabica_clean[Total Cup Points]) -> 82.3325 | AQ43: =+COUNTIF(df_arabica_clean[Country of Origin],df_arabica_clean[[#This Row],[Country of Origin]]) -> 4
A44: 179 | B44: 179 | C44: Peru | D44: Fundo La Libertad | E44: 301R | F44: Planta Callao | G44: Itochu Corporation | H44: 1600 | I44: =IF(df_arabica_clean[[#This Row],[Altitude]] <= 2500, df_arabica_clean[[#This Row],[Altitude]], ROUND(df_arabica_clean[[#This Row],[Altitude]] / 3.281, 0)) -> 1600 | J44: =IF(df_arabica_clean[[#This Row],[Altitude]]>2500,"Convertido","Original") -> Original | K44: Chanchamayo, La Merced | L44: Sandro Crispin Espiritu | M44: 275 | N44: 69 kg | O44: Japan Coffee Exchange | P44: 2022 / 2023 | Q44: July 11th, 2022 | R44: Kiichiro Iwata | S44: Caturra | T44: Completed | U44: Washed / Wet | V44: 7.5 | W44: 7.5 | X44: 7.33 | Y44: 7.5 | Z44: 7.33 | AA44: 7.33 | AB44: 10 | AC44: 10 | AD44: 10 | AE44: 7.42 | AF44: 81.92 | AG44: 11.6 | AH44: 0 | AI44: 2 | AJ44: greenish | AK44: 2 | AL44: July 11th, 2023 | AM44: Japan Coffee Exchange | AN44: 〒413-0002 静岡県熱海市伊豆山１１７３−５８ 1173-58 Izusan, Atami, Shizuoka, 413-0002 JAPAN | AO44: 松澤 宏樹 Koju Matsuzawa - +81(0)9085642901 | AP44: =AVERAGEIF(df_arabica_clean[Country of Origin],df_arabica_clean[[#This Row],[Country of Origin]],df_arabica_clean[Total Cup Points]) -> 82.3325 | AQ44: =+COUNTIF(df_arabica_clean[Country of Origin],df_arabica_clean[[#This Row],[Country of Origin]]) -> 4
A45: 38 | B45: 38 | C45: Kenya | D45: Small Holder | E45: 5516 | F45: NKG | G45: IBERO (K) LTD | H45: 1600 | I45: =IF(df_arabica_clean[[#This Row],[Altitude]] <= 2500, df_arabica_clean[[#This Row],[Altitude]], ROUND(df_arabica_clean[[#This Row],[Altitude]] / 3.281, 0)) -> 1600 | J45: =IF(df_arabica_clean[[#This Row],[Altitude]]>2500,"Convertido","Original") -> Original | K45: Central | L45: Small Holder | M45: 300 | N45: 60 kg | O45: Kenya Coffee Traders Association | P45: 2022 / 2023 | Q45: February 28th, 2023 | R45: Judith Murimi | S45: SL28 | T45: Completed | U45: Washed / Wet | V45: 8.17 | W45: 7.75 | X45: 7.83 | Y45: 7.58 | Z45: 7.92 | AA45: 8 | AB45: 10 | AC45: 10 | AD45: 10 | AE45: 8 | AF45: 85.25 | AG45: 9.2 | AH45: 0 | AI45: 0 | AJ45: greenish | AK45: 1 | AL45: February 28th, 2024 | AM45: Kenya Coffee Traders Association | AN45: P.O. Box 646 00100Nairobi, Kenya, Denniss Pritt Road, Opposite St Georges Girls Secondary School | AO45: Benson Kibicho Kamau - +254 786 821 621 | AP45: =AVERAGEIF(df_arabica_clean[Country of Origin],df_arabica_clean[[#This Row],[Country of Origin]],df_arabica_clean[Total Cup Points]) -> 83.71 | AQ45: =+COUNTIF(df_arabica_clean[Country of Origin],df_arabica_clean[[#This Row],[Country of Origin]]) -> 2
A46: 168 | B46: 168 | C46: Peru | D46: Fundo La Libertado | E46: PR138 | F46: Planta Callao | G46: Itochu Corporation | H46: 1600 | I46: =IF(df_arabica_clean[[#This Row],[Altitude]] <= 2500, df_arabica_clean[[#This Row],[Altitude]], ROUND(df_arabica_clean[[#This Row],[Altitude]] / 3.281, 0)) -> 1600 | J46: =IF(df_arabica_clean[[#This Row],[Altitude]]>2500,"Convertido","Original") -> Original | K46: Chanchamayo, La Merced | L46: Sand Crispin Espiritu | M46: 275 | N46: 69 kg | O46: Japan Coffee Exchange | P46: 2022 / 2023 | Q46: July 11th, 2022 | R46: Kiichiro Iwata | S46: Caturra | T46: Completed | U46: Washed / Wet | V46: 7.67 | W46: 7.5 | X46: 7.33 | Y46: 7.58 | Z46: 7.33 | AA46: 7.42 | AB46: 10 | AC46: 10 | AD46: 10 | AE46: 7.42 | AF46: 82.25 | AG46: 11.7 | AH46: 0 | AI46: 1 | AJ46: greenish | AK46: 3 | AL46: July 11th, 2023 | AM46: Japan Coffee Exchange | AN46: 〒413-0002 静岡県熱海市伊豆山１１７３−５８ 1173-58 Izusan, Atami, Shizuoka, 413-0002 JAPAN | AO46: 松澤 宏樹 Koju Matsuzawa - +81(0)9085642901 | AP46: =AVERAGEIF(df_arabica_clean[Country of Origin],df_arabica_clean[[#This Row],[Country of Origin]],df_arabica_clean[Total Cup Points]) -> 82.3325 | AQ46: =+COUNTIF(df_arabica_clean[Country of Origin],df_arabica_clean[[#This Row],[Country of Origin]]) -> 4
A47: 52 | B47: 52 | C47: Peru | D47: Ruya Yayu Farm | E47: The 2022 Pacific Rim Coffee Summit,PE02 | F47: no. | G47: Taiwan Coffee Laboratory | H47: 1750 | I47: =IF(df_arabica_clean[[#This Row],[Altitude]] <= 2500, df_arabica_clean[[#This Row],[Altitude]], ROUND(df_arabica_clean[[#This Row],[Altitude]] / 3.281, 0)) -> 1750 | J47: =IF(df_arabica_clean[[#This Row],[Altitude]]>2500,"Convertido","Original") -> Original | K47: Villa Rica | L47: Ruya Yayu | M47: 3 | N47: 5 kg | O47: Taiwan Coffee Laboratory 台灣咖啡研究室 | P47: 2022 | Q47: November 15th, 2022 | R47: Taiwan Coffee Laboratory 台灣咖啡研究室 | S47: Gesha | T47: Completed | U47: Washed / Wet | V47: 8 | W47: 8 | X47: 7.83 | Y47: 7.83 | Z47: 7.58 | AA47: 7.83 | AB47: 10 | AC47: 10 | AD47: 10 | AE47: 7.75 | AF47: 84.83 | AG47: 10.7 | AH47: 0 | AI47: 0 | AJ47: greenish | AK47: 0 | AL47: November 15th, 2023 | AM47: Taiwan Coffee Laboratory 台灣咖啡研究室 | AN47: QAHWAH CO., LTD 4F, No. 225, Sec. 3, Beixin Rd., Xindian Dist. New Taipei City, Taiwan | AO47: Lin, Jen-An Neil 林仁安 - 886-289116612 | AP47: =AVERAGEIF(df_arabica_clean[Country of Origin],df_arabica_clean[[#This Row],[Country of Origin]],df_arabica_clean[Total Cup Points]) -> 82.3325 | AQ47: =+COUNTIF(df_arabica_clean[Country of Origin],df_arabica_clean[[#This Row],[Country of Origin]]) -> 4
... A87: 3 | B87: 3 | C87: Costa Rica | D87: La Cumbre | E87: CQU2022017 | F87: La Montana Tarrazu MIll | G87: Coffee Quality Union | H87: 1900 | I87: =IF(df_arabica_clean[[#This Row],[Altitude]] <= 2500, df_arabica_clean[[#This Row],[Altitude]], ROUND(df_arabica_clean[[#This Row],[Altitude]] / 3.281, 0)) -> 1900 | J87: =IF(df_arabica_clean[[#This Row],[Altitude]]>2500,"Convertido","Original") -> Original | K87: Los Santos,Tarrazu | L87: Santa Maria de Dota | M87: 1 | N87: 22 kg | O87: Japan Coffee Exchange | P87: 2022 | Q87: September 21st, 2022 | R87: Coffee Quality Union | S87: Gesha | T87: Completed | U87: Washed / Wet | V87: 8.08 | W87: 8.17 | X87: 8.17 | Y87: 8.25 | Z87: 8.17 | AA87: 8.08 | AB87: 10 | AC87: 10 | AD87: 10 | AE87: 8.25 | AF87: 87.17 | AG87: 11.8 | AH87: 0 | AI87: 0 | AJ87: green | AK87: 0 | AL87: September 21st, 2023 | AM87: Japan Coffee Exchange | AN87: 〒413-0002 静岡県熱海市伊豆山１１７３−５８ 1173-58 Izusan, Atami, Shizuoka, 413-0002 JAPAN | AO87: 松澤 宏樹 Koju Matsuzawa - +81(0)9085642901 | AP87: =AVERAGEIF(df_arabica_clean[Country of Origin],df_arabica_clean[[#This Row],[Country of Origin]],df_arabica_clean[Total Cup Points]) -> 83.74 | AQ87: =+COUNTIF(df_arabica_clean[Country of Origin],df_arabica_clean[[#This Row],[Country of Origin]]) -> 8
A88: 105 | B88: 105 | C88: Colombia | G88: Coffee Quality Institute | I88: =IF(df_arabica_clean[[#This Row],[Altitude]] <= 2500, df_arabica_clean[[#This Row],[Altitude]], ROUND(df_arabica_clean[[#This Row],[Altitude]] / 3.281, 0)) -> 0 | J88: =IF(df_arabica_clean[[#This Row],[Altitude]]>2500,"Convertido","Original") -> Original | M88: 1 | N88: 1 kg | O88: Barista and Coffee Academy of Asia | P88: 2022 | Q88: September 26th, 2022 | R88: Coffee Quality Institute | T88: Completed | V88: 7.83 | W88: 7.75 | X88: 7.5 | Y88: 7.58 | Z88: 7.67 | AA88: 7.67 | AB88: 10 | AC88: 10 | AD88: 10 | AE88: 7.67 | AF88: 83.67 | AG88: 12.4 | AH88: 1 | AI88: 0 | AJ88: greenish | AK88: 9 | AL88: September 26th, 2023 | AM88: Barista and Coffee Academy of Asia | AN88: The Place Bldg., Tunasan, Muntinlupa City, Metro Manila ​Philippines | AO88: Rosario Cruz - +63 995 344 5688 | AP88: =AVERAGEIF(df_arabica_clean[Country of Origin],df_arabica_clean[[#This Row],[Country of Origin]],df_arabica_clean[Total Cup Points]) -> 83.877368 | AQ88: =+COUNTIF(df_arabica_clean[Country of Origin],df_arabica_clean[[#This Row],[Country of Origin]]) -> 19
A89: 124 | B89: 124 | C89: Colombia | D89: El Laurel | E89: 1 | F89: Hulling facility | G89: Minka coffee company LTD | H89: 1100 | I89: =IF(df_arabica_clean[[#This Row],[Altitude]] <= 2500, df_arabica_clean[[#This Row],[Altitude]], ROUND(df_arabica_clean[[#This Row],[Altitude]] / 3.281, 0)) -> 1100 | J89: =IF(df_arabica_clean[[#This Row],[Altitude]]>2500,"Convertido","Original") -> Original | K89: Sierra Nevada de Santa Marta | L89: Eric SELLIN | M89: 2 | N89: 1 kg | O89: FABB Academy of Coffee | P89: 2021 / 2022 | Q89: September 30th, 2022 | R89: piradaPKPL | S89: Caturra | T89: Completed | U89: Washed / Wet | V89: 7.67 | W89: 7.67 | X89: 7.42 | Y89: 7.75 | Z89: 7.5 | AA89: 7.75 | AB89: 10 | AC89: 10 | AD89: 10 | AE89: 7.58 | AF89: 83.33 | AG89: 13.5 | AH89: 0 | AI89: 0 | AJ89: greenish | AK89: 0 | AL89: September 30th, 2023 | AM89: FABB Academy of Coffee | AN89: FABB ACADEMY OF COFFEE 259/313 SUKHUMVIT 71 RD., SOI PRIDI BANOMYONG 15, VHADANA BKK, 10110 THAILAND | AO89: Janejira Kamonsawedkun - +(66) 095 095 9593 | AP89: =AVERAGEIF(df_arabica_clean[Country of Origin],df_arabica_clean[[#This Row],[Country of Origin]],df_arabica_clean[Total Cup Points]) -> 83.877368 | AQ89: =+COUNTIF(df_arabica_clean[Country of Origin],df_arabica_clean[[#This Row],[Country of Origin]]) -> 19
A90: 193 | B90: 193 | C90: Colombia | D90: Escalera | E90: CQU2022019 | F90: Escalera | G90: Coffee Quality Union | H90: 1300 | I90: =IF(df_arabica_clean[[#This Row],[Altitude]] <= 2500, df_arabica_clean[[#This Row],[Altitude]], ROUND(df_arabica_clean[[#This Row],[Altitude]] / 3.281, 0)) -> 1300 | J90: =IF(df_arabica_clean[[#This Row],[Altitude]]>2500,"Convertido","Original") -> Original | K90: Cauca | L90: Escalera | M90: 1 | N90: 30 kg | O90: Japan Coffee Exchange | P90: 2021 / 2022 | Q90: December 22nd, 2022 | R90: Coffee Quality Union | S90: Caturra,Colombia,Castillo | T90: Completed | U90: Washed / Wet | V90: 7.42 | W90: 7.25 | X90: 7.25 | Y90: 7.42 | Z90: 7.17 | AA90: 7.33 | AB90: 10 | AC90: 10 | AD90: 10 | AE90: 7.33 | AF90: 81.17 | AG90: 11.4 | AH90: 0 | AI90: 2 | AJ90: greenish | AK90: 2 | AL90: December 22nd, 2023 | AM90: Japan Coffee Exchange | AN90: 〒413-0002 静岡県熱海市伊豆山１１７３−５８ 1173-58 Izusan, Atami, Shizuoka, 413-0002 JAPAN | AO90: 松澤 宏樹 Koju Matsuzawa - +81(0)9085642901 | AP90: =AVERAGEIF(df_arabica_clean[Country of Origin],df_arabica_clean[[#This Row],[Country of Origin]],df_arabica_clean[Total Cup Points]) -> 83.877368 | AQ90: =+COUNTIF(df_arabica_clean[Country of Origin],df_arabica_clean[[#This Row],[Country of Origin]]) -> 19
A91: 142 | B91: 142 | C91: Colombia | D91: La Argentina | E91: CQU2022013 | F91: La Argentina | G91: Coffee Quality Union | H91: 1350 | I91: =IF(df_arabica_clean[[#This Row],[Altitude]] <= 2500, df_arabica_clean[[#This Row],[Altitude]], ROUND(df_arabica_clean[[#This Row],[Altitude]] / 3.281, 0)) -> 1350 | J91: =IF(df_arabica_clean[[#This Row],[Altitude]]>2500,"Convertido","Original") -> Original | K91: Quindio | L91: Augusto Torres | M91: 1 | N91: 12 kg | O91: Japan Coffee Exchange | P91: 2021 / 2022 | Q91: June 16th, 2022 | R91: Coffee Quality Union | S91: Typica Gesha | T91: Completed | U91: Washed / Wet | V91: 7.58 | W91: 7.5 | X91: 7.5 | Y91: 7.67 | Z91: 7.58 | AA91: 7.5 | AB91: 10 | AC91: 10 | AD91: 10 | AE91: 7.58 | AF91: 82.92 | AG91: 11.5 | AH91: 0 | AI91: 1 | AJ91: greenish | AK91: 3 | AL91: June 16th, 2023 | AM91: Japan Coffee Exchange | AN91: 〒413-0002 静岡県熱海市伊豆山１１７３−５８ 1173-58 Izusan, Atami, Shizuoka, 413-0002 JAPAN | AO91: 松澤 宏樹 Koju Matsuzawa - +81(0)9085642901 | AP91: =AVERAGEIF(df_arabica_clean[Country of Origin],df_arabica_clean[[#This Row],[Country of Origin]],df_arabica_clean[Total Cup Points]) -> 83.877368 | AQ91: =+COUNTIF(df_arabica_clean[Country of Origin],df_arabica_clean[[#This Row],[Country of Origin]]) -> 19
A92: 23 | B92: 23 | C92: Colombia | D92: El Diamante | E92: CQU2023005 | F92: El Diamante | G92: Coffee Quality Union | H92: 1350 | I92: =IF(df_arabica_clean[[#This Row],[Altitude]] <= 2500, df_arabica_clean[[#This Row],[Altitude]], ROUND(df_arabica_clean[[#This Row],[Altitude]] / 3.281, 0)) -> 1350 | J92: =IF(df_arabica_clean[[#This Row],[Altitude]]>2500,"Convertido","Original") -> Original | K92: Quindio | L92: Farm Bedoya Arango | M92: 6 | N92: 5 kg | O92: Japan Coffee Exchange | P92: 2022 | Q92: April 7th, 2023 | R92: Coffee Quality Union | S92: Castillo Paraguaycito | T92: Completed | V92: 8.08 | W92: 8 | X92: 7.83 | Y92: 8.17 | Z92: 7.75 | AA92: 7.83 | AB92: 10 | AC92: 10 | AD92: 10 | AE92: 8 | AF92: 85.67 | AG92: 11.3 | AH92: 0 | AI92: 0 | AJ92: brownish | AK92: 2 | AL92: April 6th, 2024 | AM92: Japan Coffee Exchange | AN92: 〒413-0002 静岡県熱海市伊豆山１１７３−５８ 1173-58 Izusan, Atami, Shizuoka, 413-0002 JAPAN | AO92: 松澤 宏樹 Koju Matsuzawa - +81(0)9085642901 | AP92: =AVERAGEIF(df_arabica_clean[Country of Origin],df_arabica_clean[[#This Row],[Country of Origin]],df_arabica_clean[Total Cup Points]) -> 83.877368 | AQ92: =+COUNTIF(df_arabica_clean[Country of Origin],df_arabica_clean[[#This Row],[Country of Origin]]) -> 19
A93: 178 | B93: 178 | C93: Indonesia | D93: Wahana Graha Makmur | E93: 015/1686/057 | F93: PT. Wahana Graha Makmur Medan | G93: InterAmerican Coffee | H93: 1350 | I93: =IF(df_arabica_clean[[#This Row],[Altitude]] <= 2500, df_arabica_clean[[#This Row],[Altitude]], ROUND(df_arabica_clean[[#This Row],[Altitude]] / 3.281, 0)) -> 1350 | J93: =IF(df_arabica_clean[[#This Row],[Altitude]]>2500,"Convertido","Original") -> Original | K93: Sumatra | L93: PT. Wahana Graha Makmur Group | M93: 320 | N93: 60 kg | O93: NKG Quality Service (a division of Bernhard Rothfos Intercafé AG) | P93: 2022 | Q93: August 22nd, 2022 | R93: Charles Umeano | T93: Completed | U93: Pulped natural / honey | V93: 7.67 | W93: 7.33 | X93: 7.25 | Y93: 7.67 | Z93: 7.42 | AA93: 7.25 | AB93: 10 | AC93: 10 | AD93: 10 | AE93: 7.42 | AF93: 82 | AG93: 12.5 | AH93: 0 | AI93: 0 | AJ93: bluish-green | AK93: 0 | AL93: August 22nd, 2023 | AM93: NKG Quality Service (a division of Bernhard Rothfos Intercafé AG) | AN93: Bahnhofstrasse 22 6300 Zug, Switzerland | AO93: Tirza Odermatt - +41 41 728 72 81 | AP93: =AVERAGEIF(df_arabica_clean[Country of Origin],df_arabica_clean[[#This Row],[Country of Origin]],df_arabica_clean[Total Cup Points]) -> 83.693333 | AQ93: =+COUNTIF(df_arabica_clean[Country of Origin],df_arabica_clean[[#This Row],[Country of Origin]]) -> 3
A94: 131 | B94: 131 | C94: Colombia | D94: Buenos Aires | E94: CQU2023003 | F94: Buenos Aires | G94: Coffee Quality Union | H94: 1390 | I94: =IF(df_arabica_clean[[#This Row],[Altitude]] <= 2500, df_arabica_clean[[#This Row],[Altitude]], ROUND(df_arabica_clean[[#This Row],[Altitude]] / 3.281, 0)) -> 1390 | J94: =IF(df_arabica_clean[[#This Row],[Altitude]]>2500,"Convertido","Original") -> Original | K94: Quindio | L94: Chucho Bedoya | M94: 2 | N94: 12 kg | O94: Japan Coffee Exchange | P94: 2022 | Q94: April 7th, 2023 | R94: Coffee Quality Union | S94: Red Bourbon,Caturra | T94: Completed | U94: Anaerobico 1000h | V94: 7.67 | W94: 7.67 | X94: 7.58 | Y94: 7.67 | Z94: 7.58 | AA94: 7.58 | AB94: 10 | AC94: 10 | AD94: 10 | AE94: 7.5 | AF94: 83.25 | AG94: 10.9 | AH94: 0 | AI94: 0 | AJ94: brownish | AK94: 2 | AL94: April 6th, 2024 | AM94: Japan Coffee Exchange | AN94: 〒413-0002 静岡県熱海市伊豆山１１７３−５８ 1173-58 Izusan, Atami, Shizuoka, 413-0002 JAPAN | AO94: 松澤 宏樹 Koju Matsuzawa - +81(0)9085642901 | AP94: =AVERAGEIF(df_arabica_clean[Country of Origin],df_arabica_clean[[#This Row],[Country of Origin]],df_arabica_clean[Total Cup Points]) -> 83.877368 | AQ94: =+COUNTIF(df_arabica_clean[Country of Origin],df_arabica_clean[[#This Row],[Country of Origin]]) -> 19
...

Sheet Tablas_Dinamicas 
B3: Etiquetas de fila | C3: Promedio de Promedio_TotalCup | D3: Cuenta de Muestras
B4: Guatemala | C4: 84.301429 | D4: 21
B5: Colombia | C5: 83.877368 | D5: 19
B6: Honduras | C6: 83.282308 | D6: 13
B7: Brazil | C7: 81.883 | D7: 10
B8: Costa Rica | C8: 83.74 | D8: 8
B9: Nicaragua | C9: 81.892857 | D9: 7
B10: El Salvador | C10: 81.532857 | D10: 7
B11: Peru | C11: 82.3325 | D11: 4
B12: Mexico | C12: 82.71 | D12: 4
B13: Panama | C13: 83.625 | D13: 2
B29: Promedio de Aroma | C29: Promedio de Flavor | D29: Promedio de Balance
B30: 7.7210628 | C30: 7.7447343 | D30: 7.644058

Sheet Info
A5: Ranking | B5: Pais | C5: Promedio_Cup | D5: Muestras | G5: COMPARACION DE ATRIBUTOS
A6: 1 | B6: =VLOOKUP('Tablas_Dinamicas '!B4,'Tablas_Dinamicas '!B3:D13,1,0) -> Guatemala | C6: ='Tablas_Dinamicas '!C4 -> 84.301429 | D6: ='Tablas_Dinamicas '!D4 -> 21 | G6: AROMA | H6: SABOR | I6: BALANCE
A7: 2 | B7: =VLOOKUP('Tablas_Dinamicas '!B5,'Tablas_Dinamicas '!B4:D14,1,0) -> Colombia | C7: ='Tablas_Dinamicas '!C5 -> 83.877368 | D7: ='Tablas_Dinamicas '!D5 -> 19 | G7: =GETPIVOTDATA("Promedio de Aroma",'Tablas_Dinamicas '!$B$29) -> 7.7210628 | H7: =GETPIVOTDATA("Promedio de Flavor",'Tablas_Dinamicas '!$B$29) -> 7.7447343 | I7: =GETPIVOTDATA("Promedio de Balance",'Tablas_Dinamicas '!$B$29) -> 7.644058
A8: 3 | B8: =VLOOKUP('Tablas_Dinamicas '!B6,'Tablas_Dinamicas '!B5:D15,1,0) -> Honduras | C8: ='Tablas_Dinamicas '!C6 -> 83.282308 | D8: ='Tablas_Dinamicas '!D6 -> 13
A9: 4 | B9: =VLOOKUP('Tablas_Dinamicas '!B7,'Tablas_Dinamicas '!B6:D16,1,0) -> Brazil | C9: ='Tablas_Dinamicas '!C7 -> 81.883 | D9: ='Tablas_Dinamicas '!D7 -> 10
A10: 5 | B10: =VLOOKUP('Tablas_Dinamicas '!B8,'Tablas_Dinamicas '!B7:D17,1,0) -> Costa Rica | C10: ='Tablas_Dinamicas '!C8 -> 83.74 | D10: ='Tablas_Dinamicas '!D8 -> 8
A11: 6 | B11: =VLOOKUP('Tablas_Dinamicas '!B9,'Tablas_Dinamicas '!B8:D18,1,0) -> Nicaragua | C11: ='Tablas_Dinamicas '!C9 -> 81.892857 | D11: ='Tablas_Dinamicas '!D9 -> 7
A12: 7 | B12: =VLOOKUP('Tablas_Dinamicas '!B10,'Tablas_Dinamicas '!B9:D19,1,0) -> El Salvador | C12: ='Tablas_Dinamicas '!C10 -> 81.532857 | D12: ='Tablas_Dinamicas '!D10 -> 7
A13: 8 | B13: =VLOOKUP('Tablas_Dinamicas '!B11,'Tablas_Dinamicas '!B10:D20,1,0) -> Peru | C13: ='Tablas_Dinamicas '!C11 -> 82.3325 | D13: ='Tablas_Dinamicas '!D11 -> 4
A14: 9 | B14: =VLOOKUP('Tablas_Dinamicas '!B12,'Tablas_Dinamicas '!B11:D21,1,0) -> Mexico | C14: ='Tablas_Dinamicas '!C12 -> 82.71 | D14: ='Tablas_Dinamicas '!D12 -> 4
A15: 10 | B15: =VLOOKUP('Tablas_Dinamicas '!B13,'Tablas_Dinamicas '!B12:D22,1,0) -> Panama | C15: ='Tablas_Dinamicas '!C13 -> 83.625 | D15: ='Tablas_Dinamicas '!D13 -> 2
A18: TOP 3 MEJORES CALIFICADOS
A19: =Tabla3[[#Headers],[Ranking]] -> Ranking | B19: =Tabla3[[#Headers],[Pais]] -> Pais | C19: =Tabla3[[#Headers],[Promedio_Cup]] -> Promedio_Cup | D19: =Tabla3[[#Headers],[Muestras]] -> Muestras
A20: =A6 -> 1 | B20: =VLOOKUP(A20,Tabla3[],2,0) -> Guatemala | C20: =VLOOKUP($A$20,Tabla3[],3,0) -> 84.301429 | D20: =VLOOKUP($A$20,Tabla3[],4,0) -> 21
A21: =A7 -> 2 | B21: =VLOOKUP($A$21,Tabla3[],2,0) -> Colombia | C21: =VLOOKUP($A$21,Tabla3[],3,0) -> 83.877368 | D21: =VLOOKUP($A$21,Tabla3[],4,0) -> 19
A22: =A8 -> 3 | B22: =VLOOKUP($A$22,Tabla3[],2,0) -> Honduras | C22: =VLOOKUP($A$22,Tabla3[],3,0) -> 83.282308 | D22: =VLOOKUP($A$22,Tabla3[],4,0) -> 13
A25: PUNTUACION MAS BAJA
A26: =Tabla3[[#Headers],[Ranking]] -> Ranking | B26: =Tabla3[[#Headers],[Pais]] -> Pais | C26: =Tabla3[[#Headers],[Promedio_Cup]] -> Promedio_Cup | D26: =Tabla3[[#Headers],[Muestras]] -> Muestras
A27: =A15 -> 10 | B27: =VLOOKUP($A$27,Tabla3[],2,0) -> Panama | C27: =VLOOKUP($A$27,Tabla3[],3,0) -> 83.625 | D27: =VLOOKUP($A$27,Tabla3[],4,0) -> 2
